<?xml version="1.0"?>
<robot xmlns:xacro="http://ros.org/wiki/xacro" name="prius">

  <!-- Arguments -->
  <xacro:arg name="namespace" default=""/>

  <!--- Surface properties must come first? -->
  <gazebo reference="front_left_wheel">
    <mu1>0.9</mu1>
    <mu2>0.9</mu2>
    <minDepth>0.005</minDepth>
    <kp>1e8</kp>
  </gazebo>
  <gazebo reference="front_right_wheel">
    <mu1>0.9</mu1>
    <mu2>0.9</mu2>
    <minDepth>0.005</minDepth>
    <kp>1e8</kp>
  </gazebo>
  <gazebo reference="rear_left_wheel">
    <mu1>0.9</mu1>
    <mu2>0.9</mu2>
    <minDepth>0.005</minDepth>
    <kp>1e8</kp>
  </gazebo>
  <gazebo reference="rear_right_wheel">
    <mu1>0.9</mu1>
    <mu2>0.9</mu2>
    <minDepth>0.005</minDepth>
    <kp>1e8</kp>
  </gazebo>

   <!--       
  <link name="dummy"/>
  <joint name="dummy_joint" type="fixed">
    <parent link="dummy"/>
    <child link="base_link"/>
  </joint>-->
  
  <link name="$(arg namespace)base_link">
    <inertial>
      <mass value="1" />
      <inertia ixx="0.001" ixy="0.0" ixz="0.0" iyy="0.001" iyz="0.0" izz="0.001" />
    </inertial>
  </link>
  <joint name="base_link_connection" type="fixed">
    <parent link="$(arg namespace)base_link" />
    <child link="$(arg namespace)chassis" />
    <origin xyz="1.45 0 0" rpy="0 0 1.57" />
    <axis xyz="1 0 0" />
  </joint>

  <link name="$(arg namespace)chassis">
    <visual>
      <origin xyz="0 0 0" rpy="0 0 0" />
      <geometry>
        <mesh filename="package://prius_description/meshes/hybrid_body.obj" scale="0.01 0.01 0.01" />
      </geometry>
    </visual>

    <collision name="chassis">
      <origin xyz="0.0 0.05 0.625" rpy="0 0 0" />
      <geometry>
        <box size="1.7526 2.1 0.95" />
      </geometry>
    </collision>

    <collision name="front_bumper">
      <origin xyz="0.0 -2.0 0.458488" rpy="0.0 0 0" />
      <geometry>
        <box size="1.337282 0.48 0.566691" />
      </geometry>
    </collision>

    <collision name="hood">
      <origin xyz="0.0 -1.900842 0.676305" rpy="0.341247 0 0" />
      <geometry>
        <box size="1.597968 0.493107 0.265468" />
      </geometry>
    </collision>

    <collision name="windshield">
      <origin xyz="0.0 -0.875105 1.032268" rpy="0.335476 0 0" />
      <geometry>
        <box size="1.168381 1.654253 0.272347" />
      </geometry>
    </collision>

    <collision name="top_front">
      <origin xyz="0.0 0.161236 1.386042" rpy="0.135030 0 0" />
      <geometry>
        <box size="1.279154 0.625988 0.171868" />
      </geometry>
    </collision>

    <collision name="top_rear">
      <origin xyz="0.0 0.817696 1.360069" rpy="-0.068997 0 0" />
      <geometry>
        <box size="1.285130 0.771189 0.226557" />
      </geometry>
    </collision>

    <collision name="rear_window">
      <origin xyz="0.0 1.640531 1.175126" rpy="-0.262017 0 0" />
      <geometry>
        <box size="1.267845 1.116344 0.244286" />
      </geometry>
    </collision>

    <collision name="trunk">
      <origin xyz="0.0 1.637059 0.888180" rpy="0.0 0 0" />
      <geometry>
        <box size="1.788064 1.138988 0.482746" />
      </geometry>
    </collision>

    <collision name="back_bumper">
      <origin xyz="0.0 2.054454 0.577870" rpy="0.0 0 0" />
      <geometry>
        <box size="1.781650 0.512093 0.581427" />
      </geometry>
    </collision>

    <inertial>
      <mass value="1356.0" />
      <origin xyz="0 0 0.48" rpy="0 0 1.5708" />
      <inertia ixx="2581.13354740" ixy="0.0" ixz="0.0" iyy="591.30846112" iyz="0.0" izz="2681.95008628" />
    </inertial>
  </link>
  <link name="$(arg namespace)fl_axle">
    <inertial>
      <mass value="1" />
      <origin xyz="0 0 0" />
      <inertia ixx="0.004" ixy="0.0" ixz="0.0" iyy="0.004" iyz="0.0" izz="0.004" />
    </inertial>
  </link>
  <link name="$(arg namespace)fr_axle">
    <inertial>
      <mass value="1" />
      <origin xyz="0 0 0" />
      <inertia ixx="0.004" ixy="0.0" ixz="0.0" iyy="0.004" iyz="0.0" izz="0.004" />
    </inertial>
  </link>
  <link name="$(arg namespace)front_left_wheel">
    <inertial>
      <mass value="11" />
      <origin xyz="0 0 0" />
      <inertia ixx="0.58631238" ixy="0.0" ixz="0.0" iyy="0.33552910" iyz="0.0" izz="0.33552910" />
    </inertial>
    <collision name="front_left_wheel_collision">
      <geometry>
        <sphere radius="0.31265" />
      </geometry>
    </collision>
    <visual>
      <origin xyz="0 0 0" rpy="0 0 0" />
      <geometry>
        <mesh filename="package://prius_description/meshes/wheel.obj" scale="0.01 0.01 0.01" />
      </geometry>
    </visual>
  </link>
  <link name="$(arg namespace)front_right_wheel">
    <inertial>
      <mass value="11" />
      <origin xyz="0 0 0" />
      <inertia ixx="0.58631238" ixy="0.0" ixz="0.0" iyy="0.33552910" iyz="0.0" izz="0.33552910" />
    </inertial>
    <collision name="front_right_wheel_collision">
      <geometry>
        <sphere radius="0.31265" />
      </geometry>
    </collision>
    <visual>
      <origin xyz="0 0 0" rpy="0 0 0" />
      <geometry>
        <mesh filename="package://prius_description/meshes/wheel.obj" scale="0.01 0.01 0.01" />
      </geometry>
    </visual>
  </link>
  <link name="$(arg namespace)rear_left_wheel">
    <inertial>
      <mass value="11" />
      <origin xyz="0 0 0" />
      <inertia ixx="0.58631238" ixy="0.0" ixz="0.0" iyy="0.33552910" iyz="0.0" izz="0.33552910" />
    </inertial>
    <collision name="rear_left_wheel_collision">
      <geometry>
        <sphere radius="0.31265" />
      </geometry>
    </collision>
    <visual>
      <origin xyz="0 0 0" rpy="0 0 0" />
      <geometry>
        <mesh filename="package://prius_description/meshes/wheel.obj" scale="0.01 0.01 0.01" />
      </geometry>
    </visual>
  </link>
  <link name="$(arg namespace)rear_right_wheel">
    <inertial>
      <mass value="11" />
      <origin xyz="0 0 0" />
      <inertia ixx="0.58631238" ixy="0.0" ixz="0.0" iyy="0.33552910" iyz="0.0" izz="0.33552910" />
    </inertial>
    <collision name="rear_right_wheel_collision">
      <geometry>
        <sphere radius="0.31265" />
      </geometry>
    </collision>
    <visual>
      <origin xyz="0 0 0" rpy="0 0 0" />
      <geometry>
        <mesh filename="package://prius_description/meshes/wheel.obj" scale="0.01 0.01 0.01" />
      </geometry>
    </visual>
  </link>
  <link name="$(arg namespace)steering_wheel">
    <inertial>
      <mass value="1.0" />
      <inertia ixx="0.14583300" ixy="0.0" ixz="0.0" iyy="0.14583300" iyz="0.0" izz="0.125" />
    </inertial>
    <visual>
      <origin xyz="0 0 0" rpy="1.302101 0 0" />
      <geometry>
        <mesh filename="package://prius_description/meshes/steering_wheel.obj" scale="0.01 0.01 0.01" />
      </geometry>
    </visual>
  </link>

  <joint name="steering_joint" type="continuous">
    <origin xyz="0.357734 -0.627868 0.988243" rpy="-1.302101 0 0" />
    <parent link="$(arg namespace)chassis" />
    <child link="$(arg namespace)steering_wheel" />
    <axis xyz="0 0 1" />
    <limit lower="-7.85" upper="7.85" effort="10000000" velocity="1000000" />
  </joint>

  <joint name="front_left_steer_joint" type="continuous">
    <parent link="$(arg namespace)chassis" />
    <child link="$(arg namespace)fl_axle" />
    <origin xyz="0.767 -1.41 0.3" rpy="0 0 0" />
    <axis xyz="0 0 1" />
    <limit lower="-0.8727" upper="0.8727" effort="10000000" velocity="1000000" />
  </joint>
  <joint name="front_right_steer_joint" type="continuous">
    <parent link="$(arg namespace)chassis" />
    <child link="$(arg namespace)fr_axle" />
    <origin xyz="-0.767 -1.41 0.3" rpy="0 0 0" />
    <axis xyz="0 0 1" />
    <limit lower="-0.8727" upper="0.8727" effort="10000000" velocity="1000000" />
  </joint>
  <joint name="front_left_wheel_joint" type="continuous">
    <parent link="$(arg namespace)fl_axle" />
    <child link="$(arg namespace)front_left_wheel" />
    <origin xyz="0 0 0" rpy="0 0 0" />
    <axis xyz="1 0 0" />
  </joint>
  <joint name="front_right_wheel_joint" type="continuous">
    <parent link="$(arg namespace)fr_axle" />
    <child link="$(arg namespace)front_right_wheel" />
    <origin xyz="0 0 0" rpy="0 0 0" />
    <axis xyz="1 0 0" />
  </joint>
  <joint name="rear_left_wheel_joint" type="continuous">
    <parent link="$(arg namespace)chassis" />
    <child link="$(arg namespace)rear_left_wheel" />
    <origin xyz="0.793 1.45 0.3" rpy="0 0 0" />
    <axis xyz="1 0 0" />
  </joint>
  <joint name="rear_right_wheel_joint" type="continuous">
    <parent link="$(arg namespace)chassis" />
    <child link="$(arg namespace)rear_right_wheel" />
    <origin xyz="-0.793 1.45 0.3" rpy="0 0 0" />
    <axis xyz="1 0 0" />
  </joint>

  <gazebo reference="base_link_connection">
    <disableFixedJointLumping>true</disableFixedJointLumping>
  </gazebo>

  <!-- GAZEBO -->
  <gazebo>
    <plugin name="joint_states" filename="libgazebo_ros_joint_state_publisher.so">
      <ros>
          <remapping>~/out:=joint_states</remapping>
      </ros>
      <update_rate>30</update_rate>
      <joint_name>steering_joint</joint_name>
      <joint_name>front_left_steer_joint</joint_name>
      <joint_name>front_right_steer_joint</joint_name>
      <joint_name>front_left_wheel_joint</joint_name>
      <joint_name>front_right_wheel_joint</joint_name>
      <joint_name>rear_left_wheel_joint</joint_name>
      <joint_name>rear_right_wheel_joint</joint_name>
    </plugin>
  </gazebo>
  <!-- -->
  <gazebo>
    <update_rate>100.0</update_rate>
    <plugin name='ackermann_drive' filename='libgazebo_ros_ackermann_drive.so'>
    
      <!-- wheels -->
      <front_left_joint>front_left_wheel_joint</front_left_joint>
      <front_right_joint>front_right_wheel_joint</front_right_joint>
      <rear_left_joint>rear_left_wheel_joint</rear_left_joint>
      <rear_right_joint>rear_right_wheel_joint</rear_right_joint>
      <steering_wheel_joint>steering_joint</steering_wheel_joint>
      <left_steering_joint>front_left_steer_joint</left_steering_joint>
      <right_steering_joint>front_right_steer_joint</right_steering_joint>
      
      <!-- Max absolute steer angle for tyre in radians-->
      <!-- Any cmd_vel angular z greater than this would be capped -->
      <max_steer>0.6458</max_steer>
      
      <!-- Max absolute steering angle of steering wheel -->
      <max_steering_angle>7.85</max_steering_angle>
      <!-- Max absolute linear speed in m/s -->
      <max_speed>20</max_speed>

      <!-- PID tuning -->
   
      <left_steering_pid_gain>1500 0 100</left_steering_pid_gain>
      <left_steering_i_range>0 0</left_steering_i_range>
      <right_steering_pid_gain>1500 0 100</right_steering_pid_gain>
      <right_steering_i_range>0 0</right_steering_i_range>
      <linear_velocity_pid_gain>1000 0 1</linear_velocity_pid_gain>
      <linear_velocity_i_range>0 0</linear_velocity_i_range>
      


      <!-- output -->
      <publish_odom>true</publish_odom>
      <publish_odom_tf>true</publish_odom_tf>
      <publish_wheel_tf>false</publish_wheel_tf>
      <publish_distance>true</publish_distance>
      <odometry_frame>$(arg namespace)odom</odometry_frame>
      <robot_base_frame>$(arg namespace)base_link</robot_base_frame>

      <ros> 
        <argument>--ros-args --remap cmd_vel:=cmd_vel</argument>
        <argument>--ros-args --remap odom:=odom</argument>
        <argument>--ros-args --remap distance:=distance</argument>
        <remapping>/tf:=tf</remapping>
      </ros>
  
    </plugin>
  </gazebo> 

  <link name="$(arg namespace)center_laser_link">
    <inertial>
      <origin xyz="0 0 0" rpy="0 0 0"/>
      <mass value="0.0"/>
      <inertia ixx="0.001"  ixy="0"  ixz="0" iyy="0.001" iyz="0" izz="0.001" />
    </inertial>
  </link>
    
  <joint name="center_laser_joint" type="fixed">
    <parent link="$(arg namespace)chassis"/>
    <child link="$(arg namespace)center_laser_link"/>
    <!-- <origin xyz="2.7 0 0.2" rpy="0 0 0"/> -->
    <origin xyz="0 -2.2 0.3" rpy="0 0 -1.5707"/>
  </joint>
    
  <gazebo reference="$(arg namespace)center_laser_link">
    <sensor name="center_laser_sensor" type="ray">
      <always_on>true</always_on>
      <visualize>true</visualize>
      <publish_rate>30.0</publish_rate>
      <update_rate>30.0</update_rate>
      <ray>
        <scan>
          <horizontal>
            <samples>640</samples>
            <resolution>1.000000</resolution>
            <!--
            <min_angle>-2.26889</min_angle>
            <max_angle>2.2689</max_angle>
            -->
            <min_angle>-1.2</min_angle>
            <max_angle>1.2</max_angle>
          </horizontal>
        </scan>
        <range>
          <min>0.2</min>
          <max>30</max>
          <resolution>0.015000</resolution>
        </range>
        <noise>
          <type>gaussian</type>
          <mean>0.0</mean>
          <stddev>0.01</stddev>
        </noise>
      </ray>
      <plugin name="gazebo_ros_head_hokuyo_controller" filename="libgazebo_ros_ray_sensor.so">
        <ros>
          <remapping>~/out:=base_scan</remapping>
        </ros>
        <output_type>sensor_msgs/LaserScan</output_type>
        <frame_name>$(arg namespace)center_laser_link</frame_name>
      </plugin>
    </sensor>
  </gazebo>


<!-- IMU -->
<link name="$(arg namespace)imu_link"/>

  <joint name="imu_joint" type="fixed">
    <axis xyz="0 1 0" />
    <origin xyz="0 0 0.135" rpy="0 0 0"/>
    <parent link="$(arg namespace)chassis"/>
    <child link="$(arg namespace)imu_link"/>
</joint>

  <gazebo reference="$(arg namespace)imu_link">
    <sensor name="imu_sensor" type="imu">
      <plugin filename="libgazebo_ros_imu_sensor.so" name="imu_plugin">
        <ros>
          <remapping>~/out:=imu</remapping>
        </ros>
        <initial_orientation_as_reference>false</initial_orientation_as_reference>
      </plugin>
      <always_on>true</always_on>
      <update_rate>200</update_rate>
      <visualize>true</visualize>
    </sensor>
  </gazebo>



</robot>
